<?xml version="1.0"?>
<sdf version="1.6">
  <model name="vehicle">
    <static>false</static>

    <!-- ================= BASE ================= -->
    <link name="base_link">
      <pose>0 0 0.1 0 0 0</pose>

      <inertial>
        <mass>8.0</mass>
        <inertia>
          <ixx>0.2</ixx>
          <iyy>0.2</iyy>
          <izz>0.3</izz>
        </inertia>
      </inertial>

      <collision name="collision">
        <geometry>
          <cylinder>
            <radius>0.25</radius>
            <length>0.2</length>
          </cylinder>
        </geometry>
      </collision>

      <visual name="visual">
        <geometry>
          <cylinder>
            <radius>0.25</radius>
            <length>0.2</length>
          </cylinder>
        </geometry>
        <material>
          <ambient>0.2 0.2 0.2 1</ambient>
          <diffuse>0.3 0.3 0.3 1</diffuse>
        </material>
      </visual>

      <!-- ================= LIDAR ================= -->
      <sensor name="lidar" type="ray">
        <pose>0 0 0.25 0 0 0</pose>
        <update_rate>10</update_rate>
        <ray>
          <scan>
            <horizontal>
              <samples>720</samples>
              <resolution>1</resolution>
              <min_angle>-3.14159</min_angle>
              <max_angle>3.14159</max_angle>
            </horizontal>
          </scan>
          <range>
            <min>0.12</min>
            <max>10.0</max>
            <resolution>0.01</resolution>
          </range>
        </ray>

        <plugin name="laser_plugin" filename="libgazebo_ros_ray_sensor.so">
          <ros>
            <remapping>~/out:=/scan</remapping>
          </ros>
          <output_type>sensor_msgs/LaserScan</output_type>
          <frame_name>base_link</frame_name>
          <max_wheel_torque>120.0</max_wheel_torque>
          <max_wheel_acceleration>50.0</max_wheel_acceleration>

        </plugin>
      </sensor>
    </link>

    <!-- ================= LEFT WHEEL ================= -->
    <link name="left_wheel">
      <!-- keep rotation so cylinder axis becomes wheel axle -->
      <pose>0 0.3 0.1 1.5707 0 0</pose>


      <collision name="collision">
        <geometry>
          <cylinder>
            <radius>0.1</radius>
            <length>0.10</length>  <!-- was 0.05 -->
          </cylinder>
        </geometry>
      </collision>

      <visual name="visual">
        <geometry>
          <cylinder>
            <radius>0.1</radius>
            <length>0.10</length>  <!-- was 0.05 -->
          </cylinder>
        </geometry>
        <material>
          <ambient>0 0 0 1</ambient>
          <diffuse>0 0 0 1</diffuse>
        </material>
      </visual>
    </link>

    <!-- ================= RIGHT WHEEL ================= -->
    <link name="right_wheel">
      <pose>0 -0.3 0.1 1.5707 0 0</pose>


      <collision name="collision">
        <geometry>
          <cylinder>
            <radius>0.1</radius>
            <length>0.10</length>  <!-- was 0.05 -->
          </cylinder>
        </geometry>
      </collision>

      <visual name="visual">
        <geometry>
          <cylinder>
            <radius>0.1</radius>
            <length>0.10</length>  <!-- was 0.05 -->
          </cylinder>
        </geometry>
        <material>
          <ambient>0 0 0 1</ambient>
          <diffuse>0 0 0 1</diffuse>
        </material>
      </visual>
    </link>

    <!-- ================= CASTER ================= -->
    <link name="caster">
      <pose>-0.2 0 0.05 0 0 0</pose>
      <collision name="collision">
        <geometry>
          <sphere>
            <radius>0.05</radius>
          </sphere>
        </geometry>
      </collision>
      <visual name="visual">
        <geometry>
          <sphere>
            <radius>0.05</radius>
          </sphere>
        </geometry>
      </visual>
    </link>

    <!-- ================= JOINTS ================= -->
    <joint name="left_wheel_joint" type="revolute">
      <parent>base_link</parent>
      <child>left_wheel</child>
      <axis>
        <xyz>0 0 -1</xyz>
      </axis>
    </joint>

    <joint name="right_wheel_joint" type="revolute">
      <parent>base_link</parent>
      <child>right_wheel</child>
      <axis>
        <xyz>0 0 -1</xyz>
      </axis>
    </joint>

    <joint name="caster_joint" type="fixed">
      <parent>base_link</parent>
      <child>caster</child>
    </joint>

    <!-- ================= DIFF DRIVE ================= -->
    <plugin name="diff_drive" filename="libgazebo_ros_diff_drive.so">
      <ros>
        <remapping>cmd_vel:=/cmd_vel</remapping>
      </ros>

      <left_joint>left_wheel_joint</left_joint>
      <right_joint>right_wheel_joint</right_joint>

      <wheel_separation>0.6</wheel_separation>
      <wheel_diameter>0.2</wheel_diameter>

      <publish_odom>true</publish_odom>
      <publish_odom_tf>true</publish_odom_tf>
      <publish_wheel_tf>true</publish_wheel_tf>
      <odometry_topic>odom</odometry_topic>
      <odometry_frame>odom</odometry_frame>
      <robot_base_frame>base_link</robot_base_frame>
    </plugin>

  </model>
</sdf>
